2022-08-25 09:02:30 | ERROR | An error has been caught in function '<module>', process 'MainProcess' (27920), thread 'MainThread' (25720):
Traceback (most recent call last):

> File "c:/Users/salhail/Desktop/Mot/mot/main.py", line 77, in <module>
    main()
    └ <function main at 0x0000011DAF2C00D0>

  File "c:/Users/salhail/Desktop/Mot/mot/main.py", line 58, in main
    res = model(frame)
          │     └ array([[[ 65,  80,  56],
          │               [ 60,  75,  51],
          │               [ 50,  63,  47],
          │               ...,
          │               [ 79,  94,  59],
          │               [ 68...
          └ None

TypeError: 'NoneType' object is not callable
